{"nbformat":4,"nbformat_minor":0,"metadata":{"colab":{"name":"Setup_Env.ipynb","version":"0.3.2","provenance":[]},"kernelspec":{"name":"python3","display_name":"Python 3"}},"cells":[{"cell_type":"code","metadata":{"id":"KoOu4pEP9fjH","colab_type":"code","colab":{"base_uri":"https://localhost:8080/","height":895},"outputId":"a6169b4d-e0db-4ca4-8917-9492eb9f4661","executionInfo":{"status":"error","timestamp":1565951241073,"user_tz":-540,"elapsed":831,"user":{"displayName":"Nam Hai Nguyen","photoUrl":"","userId":"04306349887236480050"}}},"source":["cd drive/"],"execution_count":25,"outputs":[{"output_type":"stream","text":["ERROR:root:Internal Python error in the inspect module.\n","Below is the traceback from this internal error.\n","\n"],"name":"stderr"},{"output_type":"stream","text":["Traceback (most recent call last):\n","  File \"/usr/local/lib/python3.6/dist-packages/IPython/core/interactiveshell.py\", line 2882, in run_code\n","    exec(code_obj, self.user_global_ns, self.user_ns)\n","  File \"<ipython-input-25-915e22aa5fdc>\", line 1, in <module>\n","    get_ipython().magic('cd drive/')\n","  File \"/usr/local/lib/python3.6/dist-packages/IPython/core/interactiveshell.py\", line 2160, in magic\n","    return self.run_line_magic(magic_name, magic_arg_s)\n","  File \"/usr/local/lib/python3.6/dist-packages/IPython/core/interactiveshell.py\", line 2081, in run_line_magic\n","    result = fn(*args,**kwargs)\n","  File \"</usr/local/lib/python3.6/dist-packages/decorator.py:decorator-gen-91>\", line 2, in cd\n","  File \"/usr/local/lib/python3.6/dist-packages/IPython/core/magic.py\", line 188, in <lambda>\n","    call = lambda f, *a, **k: f(*a, **k)\n","  File \"/usr/local/lib/python3.6/dist-packages/IPython/core/magics/osm.py\", line 288, in cd\n","    oldcwd = py3compat.getcwd()\n","FileNotFoundError: [Errno 2] No such file or directory\n","\n","During handling of the above exception, another exception occurred:\n","\n","Traceback (most recent call last):\n","  File \"/usr/local/lib/python3.6/dist-packages/IPython/core/interactiveshell.py\", line 1823, in showtraceback\n","    stb = value._render_traceback_()\n","AttributeError: 'FileNotFoundError' object has no attribute '_render_traceback_'\n","\n","During handling of the above exception, another exception occurred:\n","\n","Traceback (most recent call last):\n","  File \"/usr/local/lib/python3.6/dist-packages/IPython/core/ultratb.py\", line 1132, in get_records\n","    return _fixed_getinnerframes(etb, number_of_lines_of_context, tb_offset)\n","  File \"/usr/local/lib/python3.6/dist-packages/IPython/core/ultratb.py\", line 313, in wrapped\n","    return f(*args, **kwargs)\n","  File \"/usr/local/lib/python3.6/dist-packages/IPython/core/ultratb.py\", line 358, in _fixed_getinnerframes\n","    records = fix_frame_records_filenames(inspect.getinnerframes(etb, context))\n","  File \"/usr/lib/python3.6/inspect.py\", line 1490, in getinnerframes\n","    frameinfo = (tb.tb_frame,) + getframeinfo(tb, context)\n","  File \"/usr/lib/python3.6/inspect.py\", line 1448, in getframeinfo\n","    filename = getsourcefile(frame) or getfile(frame)\n","  File \"/usr/lib/python3.6/inspect.py\", line 696, in getsourcefile\n","    if getattr(getmodule(object, filename), '__loader__', None) is not None:\n","  File \"/usr/lib/python3.6/inspect.py\", line 725, in getmodule\n","    file = getabsfile(object, _filename)\n","  File \"/usr/lib/python3.6/inspect.py\", line 709, in getabsfile\n","    return os.path.normcase(os.path.abspath(_filename))\n","  File \"/usr/lib/python3.6/posixpath.py\", line 383, in abspath\n","    cwd = os.getcwd()\n","FileNotFoundError: [Errno 2] No such file or directory\n"],"name":"stdout"},{"output_type":"error","ename":"FileNotFoundError","evalue":"ignored","traceback":["\u001b[0;31m---------------------------------------------------------------------------\u001b[0m"]}]},{"cell_type":"code","metadata":{"id":"X6tDh-aJ96fa","colab_type":"code","colab":{"base_uri":"https://localhost:8080/","height":895},"outputId":"5531e6bd-d536-4b9b-b81b-c97f41f1dc45","executionInfo":{"status":"error","timestamp":1565951245882,"user_tz":-540,"elapsed":842,"user":{"displayName":"Nam Hai Nguyen","photoUrl":"","userId":"04306349887236480050"}}},"source":["cd drive"],"execution_count":26,"outputs":[{"output_type":"stream","text":["ERROR:root:Internal Python error in the inspect module.\n","Below is the traceback from this internal error.\n","\n"],"name":"stderr"},{"output_type":"stream","text":["Traceback (most recent call last):\n","  File \"/usr/local/lib/python3.6/dist-packages/IPython/core/interactiveshell.py\", line 2882, in run_code\n","    exec(code_obj, self.user_global_ns, self.user_ns)\n","  File \"<ipython-input-26-655d911984ce>\", line 1, in <module>\n","    get_ipython().magic('cd drive')\n","  File \"/usr/local/lib/python3.6/dist-packages/IPython/core/interactiveshell.py\", line 2160, in magic\n","    return self.run_line_magic(magic_name, magic_arg_s)\n","  File \"/usr/local/lib/python3.6/dist-packages/IPython/core/interactiveshell.py\", line 2081, in run_line_magic\n","    result = fn(*args,**kwargs)\n","  File \"</usr/local/lib/python3.6/dist-packages/decorator.py:decorator-gen-91>\", line 2, in cd\n","  File \"/usr/local/lib/python3.6/dist-packages/IPython/core/magic.py\", line 188, in <lambda>\n","    call = lambda f, *a, **k: f(*a, **k)\n","  File \"/usr/local/lib/python3.6/dist-packages/IPython/core/magics/osm.py\", line 288, in cd\n","    oldcwd = py3compat.getcwd()\n","FileNotFoundError: [Errno 2] No such file or directory\n","\n","During handling of the above exception, another exception occurred:\n","\n","Traceback (most recent call last):\n","  File \"/usr/local/lib/python3.6/dist-packages/IPython/core/interactiveshell.py\", line 1823, in showtraceback\n","    stb = value._render_traceback_()\n","AttributeError: 'FileNotFoundError' object has no attribute '_render_traceback_'\n","\n","During handling of the above exception, another exception occurred:\n","\n","Traceback (most recent call last):\n","  File \"/usr/local/lib/python3.6/dist-packages/IPython/core/ultratb.py\", line 1132, in get_records\n","    return _fixed_getinnerframes(etb, number_of_lines_of_context, tb_offset)\n","  File \"/usr/local/lib/python3.6/dist-packages/IPython/core/ultratb.py\", line 313, in wrapped\n","    return f(*args, **kwargs)\n","  File \"/usr/local/lib/python3.6/dist-packages/IPython/core/ultratb.py\", line 358, in _fixed_getinnerframes\n","    records = fix_frame_records_filenames(inspect.getinnerframes(etb, context))\n","  File \"/usr/lib/python3.6/inspect.py\", line 1490, in getinnerframes\n","    frameinfo = (tb.tb_frame,) + getframeinfo(tb, context)\n","  File \"/usr/lib/python3.6/inspect.py\", line 1448, in getframeinfo\n","    filename = getsourcefile(frame) or getfile(frame)\n","  File \"/usr/lib/python3.6/inspect.py\", line 696, in getsourcefile\n","    if getattr(getmodule(object, filename), '__loader__', None) is not None:\n","  File \"/usr/lib/python3.6/inspect.py\", line 725, in getmodule\n","    file = getabsfile(object, _filename)\n","  File \"/usr/lib/python3.6/inspect.py\", line 709, in getabsfile\n","    return os.path.normcase(os.path.abspath(_filename))\n","  File \"/usr/lib/python3.6/posixpath.py\", line 383, in abspath\n","    cwd = os.getcwd()\n","FileNotFoundError: [Errno 2] No such file or directory\n"],"name":"stdout"},{"output_type":"error","ename":"FileNotFoundError","evalue":"ignored","traceback":["\u001b[0;31m---------------------------------------------------------------------------\u001b[0m"]}]},{"cell_type":"code","metadata":{"id":"Kn9G7fhQ97qi","colab_type":"code","colab":{}},"source":[""],"execution_count":0,"outputs":[]}]}